<?xml version="1.0" encoding="utf-8"?>

<robot name="m_20iA" xmlns:xacro="https://www.ros.org/wiki/xacro">

    <!--LINKS -->

    <link name="world"/>

    <link name="base_link">
        <visual>
            <origin xyz="0 0 0" rpy="0 0 0"/>
            <geometry>
                <mesh filename="package://fanuc_description/meshes/visual/link_0.dae"/>
            </geometry>
            <material name=""/>
        </visual>
        <collision>
            <origin xyz="0 0 0" rpy="0 0 0"/>
            <geometry>
                <mesh filename="package://fanuc_description/meshes/collision/link_0.stl"/>
            </geometry>
        </collision>
    </link>

    <link name="link1">
        <visual>
            <origin xyz="0 0 0" rpy="0 0 0"/>
            <geometry>
                <mesh filename="package://fanuc_description/meshes/visual/link_1.dae"/>
            </geometry>
            <material name=""/>
        </visual>
        <collision>
            <origin xyz="0 0 0" rpy="0 0 0"/>
            <geometry>
                <mesh filename="package://fanuc_description/meshes/collision/link_1.stl"/>
            </geometry>
        </collision>
    </link>

    <link name="link2">
        <visual>
            <origin xyz="-0.15 -0.525 0" rpy="-1.5708 0 0"/>
            <geometry>
                <mesh filename="package://fanuc_description/meshes/visual/link_2.dae"/>
            </geometry>
            <material name=""/>
        </visual>
        <collision>
            <origin xyz="-0.15 -0.525 0" rpy="-1.5708 0 0"/>
            <geometry>
                <mesh filename="package://fanuc_description/meshes/collision/link_2.stl"/>
            </geometry>
        </collision>
    </link>

    <link name="link3">
        <visual>
            <origin xyz="-1.315 0.15 0" rpy="1.5708 3.14159 1.5708"/>
            <geometry>
                <mesh filename="package://fanuc_description/meshes/visual/link_3.dae"/>
            </geometry>
            <material name=""/>
        </visual>
        <collision>
            <origin xyz="-1.315 0.15 0" rpy="1.5708 3.14159 1.5708"/>
            <geometry>
                <mesh filename="package://fanuc_description/meshes/collision/link_3.stl"/>
            </geometry>
        </collision>
    </link>
    
    <link name="link4">
        <visual>
            <origin xyz="1.465 0 -0.15" rpy="0 -1.5708 0"/>
            <geometry>
                <mesh filename="package://fanuc_description/meshes/visual/link_4.dae"/>
            </geometry>
            <material name=""/>
        </visual>
        <collision>
            <origin xyz="1.465 0 -0.15" rpy="0 -1.5708 0"/>
            <geometry>
                <mesh filename="package://fanuc_description/meshes/collision/link_4.stl"/>
            </geometry>
        </collision>
    </link>
    
    <link name="link5">
        <visual>
            <origin xyz="1.465 0.985 0" rpy="1.5708 0 -1.5708"/>
            <geometry>
                <mesh filename="package://fanuc_description/meshes/visual/link_5.dae"/>
            </geometry>
            <material name=""/>
        </visual>
        <collision>
            <origin xyz="1.465 0.985 0" rpy="1.5708 0 -1.5708"/>
            <geometry>
                <mesh filename="package://fanuc_description/meshes/collision/link_5.stl"/>
            </geometry>
        </collision>
    </link>
    
    <link name="link6">
        <visual>
            <origin xyz="0 0 0.125" rpy="0 0 0"/>
            <geometry>
                <mesh filename="package://fanuc_description/meshes/visual/link_6.dae"/>
            </geometry>
            <material name=""/>
        </visual>
        <collision>
            <origin xyz="0 0 0.125" rpy="0 0 0"/>
            <geometry>
                <mesh filename="package://fanuc_description/meshes/collision/link_6.stl"/>
            </geometry>
        </collision>
    </link>
    
    <link name="flange"/>
    

    <!-- JOINTS -->
    
    <joint name="virtual_joint" type="fixed">
        <parent link="world"/>
        <child link="base_link"/>
    </joint>

    <joint name="joint1" type="revolute">
        <parent link="base_link"/>
        <child link="link1"/>
        <origin xyz="0 0 0" rpy="0 0 0"/>
        <axis xyz="0 0 1"/>
        <limit lower="-2.9670" upper="2.9670" velocity="3.40" effort="20"/>
    </joint>

    <joint name="joint2" type="revolute">
        <parent link="link1"/>
        <child link="link2"/>
        <origin xyz="0.15 0 0.525" rpy="1.5708 0 0"/>
        <axis xyz="0 0 1"/>
        <limit lower="-2.27" upper="2.27" velocity="3.05" effort="20"/>
    </joint>

    <joint name="joint3" type="revolute">
        <parent link="link2"/>
        <child link="link3"/>
        <origin xyz="0 0.79 0" rpy="0 0 1.5708"/>
        <axis xyz="0 0 1"/>
        <limit lower="-4.0" upper="4.0" velocity="3.14" effort="20"/>
    </joint>

    <joint name="joint4" type="revolute">
        <parent link="link3"/>
        <child link="link4"/>
        <origin xyz="0.15 0 0" rpy="1.5708 0 0"/>
        <axis xyz="0 0 1"/>
        <limit lower="-3.49" upper="3.49" velocity="6.28" effort="20"/>
    </joint>
    
    <joint name="joint5" type="revolute">
        <parent link="link4"/>
        <child link="link5"/>
        <origin xyz="0 0 0.860" rpy="-1.5708 0 0"/>
        <axis xyz="0 0 1"/>
        <limit lower="-3.14" upper="3.14" velocity="6.28" effort="20"/>
    </joint>
    
    <joint name="joint6" type="revolute">
        <parent link="link5"/>
        <child link="link6"/>
        <origin xyz="0 0 0" rpy="1.5708 0 0"/>
        <axis xyz="0 0 1"/>
        <limit lower="-7.855" upper="7.855" velocity="9.60" effort="20"/>
    </joint>

    <joint name="flange" type="fixed">
        <parent link="link6"/>
        <child link="flange"/>
        <origin xyz="0 0 0.1" rpy="0 0 0"/>
    </joint>
    
</robot>